created virtual environment CPython3.11.5.final.0-64 in 1865ms
  creator CPython3Posix(dest=/local/jaxgray.24325569.0/env, clear=False, no_vcs_ignore=False, global=False)
  seeder FromAppData(download=False, pip=bundle, setuptools=bundle, wheel=bundle, via=copy, app_data_dir=/home/jaxgray/.local/share/virtualenv)
    added seed packages: pip==24.1.2, setuptools==71.1.0, wheel==0.43.0
  activators BashActivator,CShellActivator,FishActivator,NushellActivator,PowerShellActivator,PythonActivator
Looking in links: /cvmfs/soft.computecanada.ca/custom/python/wheelhouse/gentoo2023/x86-64-v3, /cvmfs/soft.computecanada.ca/custom/python/wheelhouse/gentoo2023/generic, /cvmfs/soft.computecanada.ca/custom/python/wheelhouse/generic
Requirement already satisfied: pip in /local/jaxgray.24325569.0/env/lib/python3.11/site-packages (24.1.2)
Looking in links: /cvmfs/soft.computecanada.ca/custom/python/wheelhouse/gentoo2023/x86-64-v3, /cvmfs/soft.computecanada.ca/custom/python/wheelhouse/gentoo2023/generic, /cvmfs/soft.computecanada.ca/custom/python/wheelhouse/generic
Processing /cvmfs/soft.computecanada.ca/custom/python/wheelhouse/generic/cdsapi-0.2.4+computecanada-py2.py3-none-any.whl
Processing /cvmfs/soft.computecanada.ca/custom/python/wheelhouse/generic/requests-2.31.0+computecanada-py3-none-any.whl (from cdsapi)
Processing /cvmfs/soft.computecanada.ca/custom/python/wheelhouse/generic/tqdm-4.66.5+computecanada-py3-none-any.whl (from cdsapi)
Processing /cvmfs/soft.computecanada.ca/custom/python/wheelhouse/generic/charset_normalizer-3.2.0+computecanada-py3-none-any.whl (from requests>=2.5.0->cdsapi)
Processing /cvmfs/soft.computecanada.ca/custom/python/wheelhouse/generic/idna-3.4+computecanada-py3-none-any.whl (from requests>=2.5.0->cdsapi)
Processing /cvmfs/soft.computecanada.ca/custom/python/wheelhouse/generic/urllib3-2.1.0+computecanada-py3-none-any.whl (from requests>=2.5.0->cdsapi)
Processing /cvmfs/soft.computecanada.ca/custom/python/wheelhouse/generic/certifi-2024.2.2+computecanada-py3-none-any.whl (from requests>=2.5.0->cdsapi)
Installing collected packages: urllib3, tqdm, idna, charset-normalizer, certifi, requests, cdsapi
Successfully installed cdsapi-0.2.4+computecanada certifi-2024.2.2+computecanada charset-normalizer-3.2.0+computecanada idna-3.4+computecanada requests-2.31.0+computecanada tqdm-4.66.5+computecanada urllib3-2.1.0+computecanada
2024-08-23 16:59:25,935 INFO Sending request to https://cds-beta.climate.copernicus.eu/api/resources/reanalysis-era5-single-levels
Traceback (most recent call last):
  File "/project/6052872/jaxgray/isoNet_Models/Data/ERA5_Wind/downloadWindERA5.py", line 5, in <module>
    c.retrieve("reanalysis-era5-single-levels",
  File "/local/jaxgray.24325569.0/env/lib/python3.11/site-packages/cdsapi/api.py", line 310, in retrieve
    result = self._api('%s/resources/%s' % (self.url, name), request, 'POST')
             ^^^^^^^^^^^^^^^^^^^^^^^^^^^^^^^^^^^^^^^^^^^^^^^^^^^^^^^^^^^^^^^^
  File "/local/jaxgray.24325569.0/env/lib/python3.11/site-packages/cdsapi/api.py", line 344, in _api
    result = self.robust(action)(url,
             ^^^^^^^^^^^^^^^^^^^^^^^^
  File "/local/jaxgray.24325569.0/env/lib/python3.11/site-packages/cdsapi/api.py", line 512, in wrapped
    r = call(*args, **kwargs)
        ^^^^^^^^^^^^^^^^^^^^^
  File "/local/jaxgray.24325569.0/env/lib/python3.11/site-packages/requests/sessions.py", line 637, in post
    return self.request("POST", url, data=data, json=json, **kwargs)
           ^^^^^^^^^^^^^^^^^^^^^^^^^^^^^^^^^^^^^^^^^^^^^^^^^^^^^^^^^
  File "/local/jaxgray.24325569.0/env/lib/python3.11/site-packages/requests/sessions.py", line 575, in request
    prep = self.prepare_request(req)
           ^^^^^^^^^^^^^^^^^^^^^^^^^
  File "/local/jaxgray.24325569.0/env/lib/python3.11/site-packages/requests/sessions.py", line 486, in prepare_request
    p.prepare(
  File "/local/jaxgray.24325569.0/env/lib/python3.11/site-packages/requests/models.py", line 372, in prepare
    self.prepare_auth(auth, url)
  File "/local/jaxgray.24325569.0/env/lib/python3.11/site-packages/requests/models.py", line 603, in prepare_auth
    r = auth(self)
        ^^^^^^^^^^
TypeError: 'tuple' object is not callable
